Workbook
Name _174_CrPC: Droplist!$W$2:$W$10
Name Act_Type: Droplist!$E$1:$E$9
Name Bodily_Offiences: Droplist!$K$2:$K$10
Name Classification: Droplist!$G$1:$G$17
Name Crime__Against_Women: Droplist!$L$2:$L$10
Name Enforcement: Droplist!$S$2:$S$10
Name GravityType: Droplist!$C$1:$C$3
Name Missing_Cases: Droplist!$V$2:$V$10
Name NDPS: Droplist!$T$2:$T$10
Name Other_CrPC: Droplist!$Y$2:$Y$10
Name Other_IPC: Droplist!$R$2:$R$10
Name Others: Droplist!$Z$2:$Z$10
Name POCSO_Cases: Droplist!$M$2:$M$10
Name Property_Offences: Droplist!$N$2:$N$10
Name Reasons: #REF!
Name Road_Accidents: Droplist!$P$2:$P$10
Name SC_ST_Cases: Droplist!$O$2:$O$10
Name Security_Cases: Droplist!$X$2:$X$10
Name SLL: Droplist!$U$2:$U$10
Name Total: Droplist!$J$2:$J$10
Name White_Collar_Offences: Droplist!$Q$2:$Q$10

Sheet Total
A1: S.No. | B1: Sub-Division | C1: Cirlce | D1: I.O Name | E1: Police Station | F1: FIR NO | G1: ACTS & SEC | H1: FIR DT | I1: Month | J1: Year | K1: Crime Head | L1: Sub-Head | M1: Crime Classfication | N1: Act Type | O1: Gravity Type | P1: Date of charge | Q1: Return of Charge Sheet | R1: Resubmit charge sheet | S1: Stage | T1: Court Disposal | U1: Date of Police Disposal | V1: Type of Disposal | W1: Old Reason for UI | X1: Reason for UI | Y1: Reason Wise Date | Z1: Brief | AA1: TOTAL | AB1: No. of Days | AC1: Time Line | AD1: Number Pending No of days | AE1: Time Line | AF1: Sheet Holder | AG1: Merge PS Names | AH1: Time Line Actual UI Cases
A2: 1 | B2: Tekkali Sub-Division | C2: Kothuru Circle | E2: Hiramandalam | F2: '14/2016' | G2: 147, 148, 341, 342, 353, 323, 427, 435, r.w 149 IPC | H2: 42428 | I2: Feb | J2: 2016 | K2: Rioting (Unlawful Assembly) | M2: Bodily Offiences | N2: IPC | O2: Non-Grave | S2: UI | W2: For Arrest of Accused | X2: For Arrest of Accused | Z2: Occurred on 28.02.2016 at 12.00 hrs at spiil way, spill channel, earth dam at BRR Vamsadhara Reservoir, Hiramandalam village and reported on the same day at 15.00 hrs by the complainant Sri J. Srinivasa Rao, Inspector of Police, Pathapatnam Circle, wherein the accused 1. Korada Narayana Rao, District Agricultural labour union president and 14 others and some other Rehabilitees came as unlaw ful assembly along with deadly weapons like Sticks and iron rods and obstructed the BRR Project works, surrounded, beat with hands the J.Ramarao, Tahsildar, Hiramandalam and fell down. While complaint his staff saved the Tahsildar, Hiramandalam from the hands accused. Then they damaged plastic chairs, set fire to tents. Also beat the Konari Simhachalam, while trying to stop. Hence issued report by gi | AA2: Total | AB2: =IF(S2="UI",DATEDIF(H2,TODAY(),"D"),"") -> 3883 | AC2: =IF(S2="UI",IF(AB2>365,"Above 1 Year",IF(AND(AB2<=365,AB2>180),"Above 6 Months",IF(AND(AB2<=180,AB2>90),"Above 3 Months",IF(AND(AB2<=90,AB2>60),"Above 60 Days",IF(AND(AB2<=60,AB2>45),"45 to 60 Days","Below 45 Days"))))),"") -> Above 1 Year | AD2: =IF(Y2<>"",DATEDIF(Y2,TODAY(),"D"),"") | AE2: =IF(AD2<>"",IF(AD2>365,"Above 1 Year",IF(AND(AD2<=365,AD2>180),"Above 6 Months",IF(AND(AD2<=180,AD2>90),"Above 3 Months",IF(AND(AD2<=90,AD2>60),"Above 60 Days",IF(AND(AD2<=60,AD2>45),"45 to 60 Days","Below 45 Days"))))),"") | AF2: D-6(Bodily) | AG2: Hiramandalam,'14/2016' | AH2: =IF(X2="SC/PRC/CC No. Awaited","",AC2) -> Above 1 Year
A3: 2 | B3: Tekkali Sub-Division | C3: Narasannapeta Circle | E3: Narasannapeta | F3: '67/2016' | G3: 403,409,420 IPC | H3: 42504 | I3: May | J3: 2016 | K3: Criminial Misappropriation | M3: White Collar Offences | N3: IPC | O3: Non-Grave | P3: 42936 | S3: UI | W3: SC/PRC/CC No. Awaited | X3: SC/PRC/CC No. Awaited | Y3: 42936 | Z3: THIS IS A CASE OF MISAPPROPRIATION. IN 2010 TO 2011 FERTILIZERS ARE MISAPPROPRIATION INPRIMARY AGRICULTURAL SOCIETY THROUGHT THE PADALA NAGESWARARAO, HE IS WORKING AS A SECRETORY. THE TOTAL AMOUNT OF MISAPPROPRIATION IS 1,10,000/-. | AA3: Total | AB3: =IF(S3="UI",DATEDIF(H3,TODAY(),"D"),"") -> 3807 | AC3: =IF(S3="UI",IF(AB3>365,"Above 1 Year",IF(AND(AB3<=365,AB3>180),"Above 6 Months",IF(AND(AB3<=180,AB3>90),"Above 3 Months",IF(AND(AB3<=90,AB3>60),"Above 60 Days",IF(AND(AB3<=60,AB3>45),"45 to 60 Days","Below 45 Days"))))),"") -> Above 1 Year | AD3: =IF(Y3<>"",DATEDIF(Y3,TODAY(),"D"),"") -> 3375 | AE3: =IF(AD3<>"",IF(AD3>365,"Above 1 Year",IF(AND(AD3<=365,AD3>180),"Above 6 Months",IF(AND(AD3<=180,AD3>90),"Above 3 Months",IF(AND(AD3<=90,AD3>60),"Above 60 Days",IF(AND(AD3<=60,AD3>45),"45 to 60 Days","Below 45 Days"))))),"") -> Above 1 Year | AF3: D-6(White collar) | AG3: Narasannapeta,'67/2016' | AH3: =IF(X3="SC/PRC/CC No. Awaited","",AC3)
A4: 3 | B4: Tekkali Sub-Division | C4: 0 | E4: Tekkali PS | F4: '44/2017' | G4: 420,403,406 IPC | H4: 42816 | I4: Mar | J4: 2017 | K4: Criminial Misappropriation | M4: White Collar Offences | N4: IPC | O4: Non-Grave | P4: 42949 | S4: UI | W4: SC/PRC/CC No. Awaited | X4: SC/PRC/CC No. Awaited | Y4: 42949 | Z4: The complainant M. Thyagaraja, Asst. Manager (General), O/o District Manager, A.P.S.C.S.C.L., Srikakulam reported that during KMS 2016-17, a quantity of 798.920 Mts of paddy has been issued to the accused Ratnala Prasada Rao, S/o. late Venkata Rao, Proprietor, M/S RVR Enterprises, C/o. Krisna MRM, Tekkali. The miller has to deliver a quantity of 535.276 MTs of custom milled rice to APSCSCL towards resultant rice @ 67%. On review of CMR deliveries by the Rice millers in the district, it is observed that the accused has not delivered single grain towards custom milled rice against KMS 2016-17. On 21.3.2017 when the complainant surprisely visited the mill of the accused then the complainant found out of the 798.920 MTs of paddy issued for custom milling, only 81.600 MTS of paddy is availab | AA4: Total | AB4: =IF(S4="UI",DATEDIF(H4,TODAY(),"D"),"") -> 3495 | AC4: =IF(S4="UI",IF(AB4>365,"Above 1 Year",IF(AND(AB4<=365,AB4>180),"Above 6 Months",IF(AND(AB4<=180,AB4>90),"Above 3 Months",IF(AND(AB4<=90,AB4>60),"Above 60 Days",IF(AND(AB4<=60,AB4>45),"45 to 60 Days","Below 45 Days"))))),"") -> Above 1 Year | AD4: =IF(Y4<>"",DATEDIF(Y4,TODAY(),"D"),"") -> 3362 | AE4: =IF(AD4<>"",IF(AD4>365,"Above 1 Year",IF(AND(AD4<=365,AD4>180),"Above 6 Months",IF(AND(AD4<=180,AD4>90),"Above 3 Months",IF(AND(AD4<=90,AD4>60),"Above 60 Days",IF(AND(AD4<=60,AD4>45),"45 to 60 Days","Below 45 Days"))))),"") -> Above 1 Year | AF4: D-6(White collar) | AG4: Tekkali PS,'44/2017' | AH4: =IF(X4="SC/PRC/CC No. Awaited","",AC4)
A5: 4 | B5: Tekkali Sub-Division | C5: Kothuru Circle | E5: Hiramandalam | F5: '54/2017' | G5: 148,147,353,506 r/w 149 IPC, 7 CLA-1932 | H5: 42957 | I5: Aug | J5: 2017 | K5: Rioting (Unlawful Assembly) | M5: Bodily Offiences | N5: IPC | O5: Non-Grave | S5: UI | W5: For Arrest of Accused | X5: For Arrest of Accused | Z5: The Complainant Report Copy was Enclosed herewith Uploaded for the favour of Perusal. 1) Gavara Govinda Rao, s/o lt. Tellanna, 50 years, Kapu, Garlapadu village, Hiramandalam Mandal. 2) Madapana Ganapathi Rao S/o Laxminarayana, age 38 yrs, Kapu, Garlapadu village, Hiramandalam Mandal. 3) Agathamudi Jayamma, w/o Balanaidu, 50 yrs, Kapu, Garlapadu village, Hiramandalam Mandal. 4) Gedela laxmi, w/o lt. Gaddem Naidu, 30 yrs, Kapu, Garlapadu village, Hiramandalam Mandal. 5) Buri Krishnaveni, w/o Seshagiri, 30 years, Kapu, Garlapadu village,Hiramandalam Mandal. 6)Madapana Appa Rao, s/o Mukhalingam, 50 years, Kapu, Garlapadu village, Hiramandalam Mandal. 7) Vanjarapu. Rama Rao, s/o lt. Appanna, 65 years, Kapu, Garlapadu village, Hiramandalam Mandal. 8) Palli Jagannadha Rao, s/o La | AA5: Total | AB5: =IF(S5="UI",DATEDIF(H5,TODAY(),"D"),"") -> 3354 | AC5: =IF(S5="UI",IF(AB5>365,"Above 1 Year",IF(AND(AB5<=365,AB5>180),"Above 6 Months",IF(AND(AB5<=180,AB5>90),"Above 3 Months",IF(AND(AB5<=90,AB5>60),"Above 60 Days",IF(AND(AB5<=60,AB5>45),"45 to 60 Days","Below 45 Days"))))),"") -> Above 1 Year | AD5: =IF(Y5<>"",DATEDIF(Y5,TODAY(),"D"),"") | AE5: =IF(AD5<>"",IF(AD5>365,"Above 1 Year",IF(AND(AD5<=365,AD5>180),"Above 6 Months",IF(AND(AD5<=180,AD5>90),"Above 3 Months",IF(AND(AD5<=90,AD5>60),"Above 60 Days",IF(AND(AD5<=60,AD5>45),"45 to 60 Days","Below 45 Days"))))),"") | AF5: D-6(Bodily) | AG5: Hiramandalam,'54/2017' | AH5: =IF(X5="SC/PRC/CC No. Awaited","",AC5) -> Above 1 Year
A6: 5 | B6: Tekkali Sub-Division | C6: Kothuru Circle | E6: Hiramandalam | F6: '56/2017' | G6: 147, 148, 353, 506, 188 r.w 149 IPC & Sec.7 (1)(a) of Criminal Law Amendment Act-1932 | H6: 42963 | I6: Aug | J6: 2017 | K6: Rioting (Unlawful Assembly) | M6: Bodily Offiences | N6: IPC | O6: Non-Grave | S6: UI | W6: For Arrest of Accused | X6: For Arrest of Accused | Z6: Occurred on 16.08.2017 at about 11.00 hrs and reported same day at 14.00 hrs by the Complainant Sri.M.Kali Prasad, Tahasildar & Mandal Executive Magistrate of Hiramandalam and stated that at Tulagam fields the Accused about 100 members of displaced villagers of Tulagam, Duggupuram and Padali Villagers were came with supported with Gorle Ram Sankar under along with rehabilitiees were came and taken them with deadly weapons and stowed sticks and raised slogans and told them stop the works of Vamsadhara Reservoir BRR Project and warned immediately stop the works and otherwise we attack workers and vehicles go back and they were obstructing the public servants their legitimate duties and then the complainant reported against the accused persons. | AA6: Total | AB6: =IF(S6="UI",DATEDIF(H6,TODAY(),"D"),"") -> 3348 | AC6: =IF(S6="UI",IF(AB6>365,"Above 1 Year",IF(AND(AB6<=365,AB6>180),"Above 6 Months",IF(AND(AB6<=180,AB6>90),"Above 3 Months",IF(AND(AB6<=90,AB6>60),"Above 60 Days",IF(AND(AB6<=60,AB6>45),"45 to 60 Days","Below 45 Days"))))),"") -> Above 1 Year | AD6: =IF(Y6<>"",DATEDIF(Y6,TODAY(),"D"),"") | AE6: =IF(AD6<>"",IF(AD6>365,"Above 1 Year",IF(AND(AD6<=365,AD6>180),"Above 6 Months",IF(AND(AD6<=180,AD6>90),"Above 3 Months",IF(AND(AD6<=90,AD6>60),"Above 60 Days",IF(AND(AD6<=60,AD6>45),"45 to 60 Days","Below 45 Days"))))),"") | AF6: D-6(Bodily) | AG6: Hiramandalam,'56/2017' | AH6: =IF(X6="SC/PRC/CC No. Awaited","",AC6) -> Above 1 Year
A7: 6 | B7: Tekkali Sub-Division | C7: Kothuru Circle | E7: Hiramandalam | F7: '58/2017' | G7: 147, 148, 341, 332, 353, 506, 188 r.w 149 IPC & Sec.7 (1) (a) Of Criminal Law Amendment Act-1932 | H7: 42963 | I7: Aug | J7: 2017 | K7: Rioting (Unlawful Assembly) | M7: Bodily Offiences | N7: IPC | O7: Non-Grave | S7: UI | W7: For Arrest of Accused | X7: For Arrest of Accused | Z7: Occurred on 16-08-2017 at about 15.10 hrs and reported same day at 18.30 hrs by the Complainant Chamtula Rama Rao S/o.late Tatababu, age 34 yrs, Caste by Kapu, Kintali Village, Madugula Mandal of Visakhapatnam District and worked as Sub-inspector of Police, Laveru Police Station and doing duty at Hiramandalam Police Station limits and Duggupuram to Padali villages beside fields and the Complainant protect the workers of BRR Vamsadhar project mud works in the same time the rehabilitates of Duggpuram and Padali Villagers and came and with stone, deadly weapons and stowed sticks and tried to attacked the Public servants of Police, while they were obstructing the legitimate duties of them and the complainant lodges a report against the accused person of Lothugedda Sundaranarayana and others 46 | AA7: Total | AB7: =IF(S7="UI",DATEDIF(H7,TODAY(),"D"),"") -> 3348 | AC7: =IF(S7="UI",IF(AB7>365,"Above 1 Year",IF(AND(AB7<=365,AB7>180),"Above 6 Months",IF(AND(AB7<=180,AB7>90),"Above 3 Months",IF(AND(AB7<=90,AB7>60),"Above 60 Days",IF(AND(AB7<=60,AB7>45),"45 to 60 Days","Below 45 Days"))))),"") -> Above 1 Year | AD7: =IF(Y7<>"",DATEDIF(Y7,TODAY(),"D"),"") | AE7: =IF(AD7<>"",IF(AD7>365,"Above 1 Year",IF(AND(AD7<=365,AD7>180),"Above 6 Months",IF(AND(AD7<=180,AD7>90),"Above 3 Months",IF(AND(AD7<=90,AD7>60),"Above 60 Days",IF(AND(AD7<=60,AD7>45),"45 to 60 Days","Below 45 Days"))))),"") | AF7: D-6(Bodily) | AG7: Hiramandalam,'58/2017' | AH7: =IF(X7="SC/PRC/CC No. Awaited","",AC7) -> Above 1 Year
A8: 7 | B8: Srikakulam Sub-Division | C8: J.R.Puram Circle | E8: Etcherla | F8: '173/2017' | G8: Man Missing Person | H8: 43000 | I8: Sep | J8: 2017 | K8: Missing Cases | L8: Man Missing | M8: Missing Cases | N8: Missing | O8: Non-Grave | S8: UI | W8: Pending records from other depts., | X8: Pending records from other depts., | Y8: 46030 | Z8: OCCURRED ON 18..09..2017 AT ABOUT 09.00 HOURS AT ALLINAGRAM VILLAGE, ETCHERLA MANDAL, SRIKAKULAM DISTRICT AND REPORTD BY THE COMPLAINANT KILLO CHITTIBABU S/O SHONNU, 25 YEARS, ST GOWDA BY CASTE,MARRIPALEM VILLAGE, PADERU MANDAL, VISAKHAPATNAM DISTRICT IN WHICH IT IS INFORMED THAT ONE KILLO LAKSHMANARAO S/O ADDANNA, 36 YEARS, ST GOWDA BY CASTE, GONDURU VILLAGE, DOKULURU POST, PADEROO MANDAL WHO IS BROTHER OF THE COMPLAINANT AND 4 OTHER ARE CAME TO COOLI WORKS ON 15..08..2017 BHAGIRADHA BORU WELLS WORKS OF DUBBAKULA RAKESH NATIVE OF MURAPAKA VILLAGE, LAVERU MANDAL, SRIKAKULAM DISTRICT.IN THIS REGUARD THEY ARE WORKING BORU WELL WORKS AT ALLINAGARAM VILLAGE FROM 2 DAY WHILE ON 18..09..2017 AT 09.00 HOURS KILLO LAXMANA RAO CON’T DO THIS WORK I AM GOING TO MY HOUSE AND ASKING SOME MONEY FOR C | AA8: Total | AB8: =IF(S8="UI",DATEDIF(H8,TODAY(),"D"),"") -> 3311 | AC8: =IF(S8="UI",IF(AB8>365,"Above 1 Year",IF(AND(AB8<=365,AB8>180),"Above 6 Months",IF(AND(AB8<=180,AB8>90),"Above 3 Months",IF(AND(AB8<=90,AB8>60),"Above 60 Days",IF(AND(AB8<=60,AB8>45),"45 to 60 Days","Below 45 Days"))))),"") -> Above 1 Year | AD8: =IF(Y8<>"",DATEDIF(Y8,TODAY(),"D"),"") -> 281 | AE8: =IF(AD8<>"",IF(AD8>365,"Above 1 Year",IF(AND(AD8<=365,AD8>180),"Above 6 Months",IF(AND(AD8<=180,AD8>90),"Above 3 Months",IF(AND(AD8<=90,AD8>60),"Above 60 Days",IF(AND(AD8<=60,AD8>45),"45 to 60 Days","Below 45 Days"))))),"") -> Above 6 Months | AF8: D-4(Missing) | AG8: Etcherla,'173/2017' | AH8: =IF(X8="SC/PRC/CC No. Awaited","",AC8) -> Above 1 Year
A9: 8 | B9: Kasibugga Sub-Division | C9: 0 | E9: Kasibugga | F9: '33/2018' | G9: 143,283,341 r.w 149 IPC | H9: 43144 | I9: Feb | J9: 2018 | K9: Other IPC | M9: Other IPC | N9: IPC | O9: Non-Grave | S9: UI | W9: SC/PRC/CC No. Awaited | X9: SC/PRC/CC No. Awaited | Y9: 46197 | Z9: ON OCCURRED AT 30.01.2018 AT 10.30 AM TO 16.30 PM HRS THE REPORTED THAT 13.02.2018 AT 21.00 HRS THE COMPLAINANT REPORTED THAT HIS GO TO ON TRAFIC DUTY WITH KASIBUGGA TOWN PARIMISSION WITH STATION HOUSE OFFICER THEN THE OCCURRENCE TIME WAS COMING SOME PERSONS DHARNA WITH CASHEW STATUE IN PALASA AND PUBLIC INCONVENCE AND TRAFIC JAM IN CONTUNE TO 3 ROAD JUNCTION WITHOUT INTIMATION SO FORTHRE ACTION TO THAT PERSONS THE CASE WAS REGISTER CR NO 33/2018 U/S 143,283,341,R/W149 IPC OF KASIBUGGA POLICE STATION | AA9: Total | AB9: =IF(S9="UI",DATEDIF(H9,TODAY(),"D"),"") -> 3167 | AC9: =IF(S9="UI",IF(AB9>365,"Above 1 Year",IF(AND(AB9<=365,AB9>180),"Above 6 Months",IF(AND(AB9<=180,AB9>90),"Above 3 Months",IF(AND(AB9<=90,AB9>60),"Above 60 Days",IF(AND(AB9<=60,AB9>45),"45 to 60 Days","Below 45 Days"))))),"") -> Above 1 Year | AD9: =IF(Y9<>"",DATEDIF(Y9,TODAY(),"D"),"") -> 114 | AE9: =IF(AD9<>"",IF(AD9>365,"Above 1 Year",IF(AND(AD9<=365,AD9>180),"Above 6 Months",IF(AND(AD9<=180,AD9>90),"Above 3 Months",IF(AND(AD9<=90,AD9>60),"Above 60 Days",IF(AND(AD9<=60,AD9>45),"45 to 60 Days","Below 45 Days"))))),"") -> Above 3 Months | AF9: D-6(Other IPC) | AG9: Kasibugga,'33/2018' | AH9: =IF(X9="SC/PRC/CC No. Awaited","",AC9)
A10: 9 | B10: Srikakulam Sub-Division | C10: Srikakulam Rural Circle | E10: Gara | F10: '91/2018' | G10: 306 IPC | H10: 43276 | I10: Jun | J10: 2018 | K10: Other IPC | M10: Other IPC | N10: IPC | O10: Non-Grave | P10: 43554 | S10: UI | W10: SC/PRC/CC No. Awaited | X10: SC/PRC/CC No. Awaited | Y10: 43554 | Z10: Occurred on 25.06.2018 prior to 00.30 hrs at Cheekati Suryanarayana slabbed house at Mogadalapadu village, Vatsvalsa pnchayat, Gara mandal and reported on the morning at 09.099 hrs, in which the complainant Kinthali Padmaja w/o late Srinivasa rao, 35 yrs, Kalinga vysya caste, . No. 1-24-100/A, Bavaji Nagar, Balaga, Srikakulam reported that prior to 20 years she was married with her husband and they blessed a son Poorna Chandu(17) daughter Harika. Her husband worked as R.M.P. at Komaravanipeta, Mogadalapadu villages of Gara mandal and also doing chits business. While constructed a house and not maintaining the chits properly, so her husband financially loss. Since 5 years her mother-in-law harassed her husband that her husband construct the house in the name of her mother-in-law, for cle | AA10: Total | AB10: =IF(S10="UI",DATEDIF(H10,TODAY(),"D"),"") -> 3035 | AC10: =IF(S10="UI",IF(AB10>365,"Above 1 Year",IF(AND(AB10<=365,AB10>180),"Above 6 Months",IF(AND(AB10<=180,AB10>90),"Above 3 Months",IF(AND(AB10<=90,AB10>60),"Above 60 Days",IF(AND(AB10<=60,AB10>45),"45 to 60 Days","Below 45 Days"))))),"") -> Above 1 Year | AD10: =IF(Y10<>"",DATEDIF(Y10,TODAY(),"D"),"") -> 2757 | AE10: =IF(AD10<>"",IF(AD10>365,"Above 1 Year",IF(AND(AD10<=365,AD10>180),"Above 6 Months",IF(AND(AD10<=180,AD10>90),"Above 3 Months",IF(AND(AD10<=90,AD10>60),"Above 60 Days",IF(AND(AD10<=60,AD10>45),"45 to 60 Days","Below 45 Days"))))),"") -> Above 1 Year | AF10: D-6(Other IPC) | AG10: Gara,'91/2018' | AH10: =IF(X10="SC/PRC/CC No. Awaited","",AC10)
A11: 10 | B11: Srikakulam Sub-Division | C11: Srikakulam Rural Circle | E11: Srikakulam I Town | F11: '9/2019' | G11: 420 IPC, 66-C,66-D ITA-2000-2008 | H11: 43483 | I11: Jan | J11: 2019 | K11: Cyber Crime offences | M11: Cyber Crime offences | N11: IPC | O11: Non-Grave | S11: UI | W11: Want of clues | X11: Want of clues | Z11: This is a case of cheating by personation by means of electronic device that occurred on 17.01.2019 at 1230 hours at State Bank of India, Main Branch, Srikakulam town and reported belatedly on 18.01.2019 at 1800 hours by the complainant Dusi Surya Prakash,S/o. Late Sundara Ramarao, age 63 years, Brhmin by caste, Door No. 1-41-26, Bharathi nagar, Hospital Road, Balaga, Srikakulam town is retired SBI Manager, Srikakulam that on 17.01.2019 at 1230 hours, some unknown caller Santhosh Sharma made a call from SIM No. 8789129706 to his SIM No. 9440116227 ATM Verification asking for his Account No.10718089866,OTP and Personal deatils and unfortunately without knowing he provide all the required details un known caller asking me which includes OTP also. on the pretext that his account was in troubl | AA11: Total | AB11: =IF(S11="UI",DATEDIF(H11,TODAY(),"D"),"") -> 2828 | AC11: =IF(S11="UI",IF(AB11>365,"Above 1 Year",IF(AND(AB11<=365,AB11>180),"Above 6 Months",IF(AND(AB11<=180,AB11>90),"Above 3 Months",IF(AND(AB11<=90,AB11>60),"Above 60 Days",IF(AND(AB11<=60,AB11>45),"45 to 60 Days","Below 45 Days"))))),"") -> Above 1 Year | AD11: =IF(Y11<>"",DATEDIF(Y11,TODAY(),"D"),"") | AE11: =IF(AD11<>"",IF(AD11>365,"Above 1 Year",IF(AND(AD11<=365,AD11>180),"Above 6 Months",IF(AND(AD11<=180,AD11>90),"Above 3 Months",IF(AND(AD11<=90,AD11>60),"Above 60 Days",IF(AND(AD11<=60,AD11>45),"45 to 60 Days","Below 45 Days"))))),"") | AF11: Cyber Cell | AG11: Srikakulam I Town,'9/2019' | AH11: =IF(X11="SC/PRC/CC No. Awaited","",AC11) -> Above 1 Year
A12: 11 | B12: Srikakulam Sub-Division | C12: Srikakulam Rural Circle | D12: CI-Srikakulam Rural Circle | E12: Srikakulam Rural | F12: '20/2019' | G12: 380,302 IPC | H12: 43503 | I12: Feb | J12: 2019 | K12: Murder for gain | L12: Murder for gain | M12: Property Offences | N12: IPC | O12: Grave | S12: UI | W12: For Arrest of Accused | X12: For Arrest of Accused | Z12: Occurred on 07.02.19 in between 09.00 Hrs to 17.30 Hrs at Plot No S2/7-28, Viziaynagar Colony, Bondhilipuram, Chapuram Panchayat Srikakulam Rural Mandal and reported on the same day at 22.00 Hrs where in the complaint Abdhul Zilani S/o Abdhul Kuddhus, Age 38 Yrs., Caste by Muslium, Plot No S2/7-28, Viziaynagar Colony, Bondhilipuram, Chapuram Panchayat Srikakulam Rural Mandal reported that he is living by doing “Prince Foot Wear” business at Srikakulam , and he is residing at above said address along with his two sons by names Jafar 16 yrs , Nishan 13 Yrs, his wife by name Abdhul Mehur Nisha-35 Yrs and his mother Jhorona Bhai 67 Yrs. On 07.02.19 at 09.00 Hrs he went to Rajam and Ranasthalam Villages for Weekly collections, and at 17.30 Hrs he received a phone call from his elder son that hi | AA12: Total | AB12: =IF(S12="UI",DATEDIF(H12,TODAY(),"D"),"") -> 2808 | AC12: =IF(S12="UI",IF(AB12>365,"Above 1 Year",IF(AND(AB12<=365,AB12>180),"Above 6 Months",IF(AND(AB12<=180,AB12>90),"Above 3 Months",IF(AND(AB12<=90,AB12>60),"Above 60 Days",IF(AND(AB12<=60,AB12>45),"45 to 60 Days","Below 45 Days"))))),"") -> Above 1 Year | AD12: =IF(Y12<>"",DATEDIF(Y12,TODAY(),"D"),"") | AE12: =IF(AD12<>"",IF(AD12>365,"Above 1 Year",IF(AND(AD12<=365,AD12>180),"Above 6 Months",IF(AND(AD12<=180,AD12>90),"Above 3 Months",IF(AND(AD12<=90,AD12>60),"Above 60 Days",IF(AND(AD12<=60,AD12>45),"45 to 60 Days","Below 45 Days"))))),"") | AF12: D-3 & D-5 (CAW) | AG12: Srikakulam Rural,'20/2019' | AH12: =IF(X12="SC/PRC/CC No. Awaited","",AC12) -> Above 1 Year
A13: 12 | B13: Srikakulam Sub-Division | C13: 0 | E13: Srikakulam II Town | F13: '13/2019' | G13: 420 IPC, 66-C,66-D ITA-2000-2008 | H13: 43506 | I13: Feb | J13: 2019 | K13: Cyber Crime offences | M13: Cyber Crime offences | N13: IPC | O13: Non-Grave | S13: UI | W13: For Suspect Verification | X13: Want of clues | Z13: This is a case of cheating coupled with using pass word of another person and also cheating duly using computer resource occurred on 09.02.2019 at 13.45 hrs at Rainbow hospital, Srikakulam town and reported on 10.02.2019 at 11.00 hrs, wherein the complt. Palla Suribabu s/o Yerrayya, 33 yrs, Yadav by caste, Byri vill, Srikakulam rural mandalam reported that some unknown person had cheated him and withdrew the amounts spells-wise to a total of Rs. 1,10,900/- through computer resource by using his ATM card, PIN and OTP number. | AA13: Total | AB13: =IF(S13="UI",DATEDIF(H13,TODAY(),"D"),"") -> 2805 | AC13: =IF(S13="UI",IF(AB13>365,"Above 1 Year",IF(AND(AB13<=365,AB13>180),"Above 6 Months",IF(AND(AB13<=180,AB13>90),"Above 3 Months",IF(AND(AB13<=90,AB13>60),"Above 60 Days",IF(AND(AB13<=60,AB13>45),"45 to 60 Days","Below 45 Days"))))),"") -> Above 1 Year | AD13: =IF(Y13<>"",DATEDIF(Y13,TODAY(),"D"),"") | AE13: =IF(AD13<>"",IF(AD13>365,"Above 1 Year",IF(AND(AD13<=365,AD13>180),"Above 6 Months",IF(AND(AD13<=180,AD13>90),"Above 3 Months",IF(AND(AD13<=90,AD13>60),"Above 60 Days",IF(AND(AD13<=60,AD13>45),"45 to 60 Days","Below 45 Days"))))),"") | AF13: Cyber Cell | AG13: Srikakulam II Town,'13/2019' | AH13: =IF(X13="SC/PRC/CC No. Awaited","",AC13) -> Above 1 Year
A14: 13 | B14: Kasibugga Sub-Division | C14: Sompeta Circle | E14: Sompeta | F14: '24/2019' | G14: 174 CrPC | H14: 43549 | I14: Mar | J14: 2019 | K14: 174 CrPC | M14: 174 CrPC | N14: 174 CrPC | O14: Non-Grave | S14: UI | W14: Pending records from other depts., | X14: Pending records from other depts., | Y14: 45432 | Z14: on 25-03-2019 at 10-00 hrs the complainant Palavalasa Kalyani, w/o Sriramurty, age 28yrs, caste by Kalinga, working as process server, VI Additional Dist. Judge, Sompeta, residents of Geetha cable street, Sompeta lodged a written report stating that she is working as process server, VI Additional Dist. Judge, Sompeta since 2015. Every day morning at 08-00 hrs she attending Banglow duty at VI Additional Dist. Judge Madam House. As usually, today, i.e. on 25-3-2019 morning at about 08-00 hours she attending Bunglow duty i.e. the house of Judge Madam situated at BC colony, Kothapeta street belongs to Vysyaraju Gopi Kiran. She along with sweeper Urmila knocked the doors and pressed the calling bell. But no response. Due to suspicion, she informed their court staff Baburao, Sur | AA14: Total | AB14: =IF(S14="UI",DATEDIF(H14,TODAY(),"D"),"") -> 2762 | AC14: =IF(S14="UI",IF(AB14>365,"Above 1 Year",IF(AND(AB14<=365,AB14>180),"Above 6 Months",IF(AND(AB14<=180,AB14>90),"Above 3 Months",IF(AND(AB14<=90,AB14>60),"Above 60 Days",IF(AND(AB14<=60,AB14>45),"45 to 60 Days","Below 45 Days"))))),"") -> Above 1 Year | AD14: =IF(Y14<>"",DATEDIF(Y14,TODAY(),"D"),"") -> 879 | AE14: =IF(AD14<>"",IF(AD14>365,"Above 1 Year",IF(AND(AD14<=365,AD14>180),"Above 6 Months",IF(AND(AD14<=180,AD14>90),"Above 3 Months",IF(AND(AD14<=90,AD14>60),"Above 60 Days",IF(AND(AD14<=60,AD14>45),"45 to 60 Days","Below 45 Days"))))),"") -> Above 1 Year | AF14: D-4(174 CrPC) | AG14: Sompeta,'24/2019' | AH14: =IF(X14="SC/PRC/CC No. Awaited","",AC14) -> Above 1 Year
A15: 14 | B15: Tekkali Sub-Division | C15: Narasannapeta Circle | E15: Polaki | F15: '88/2019' | G15: Man Missing Person | H15: 43558 | I15: Apr | J15: 2019 | K15: Missing Cases | L15: Man Missing | M15: Missing Cases | N15: Missing | O15: Non-Grave | S15: UI | W15: Want of clues | X15: Want of clues | Z15: This is a case of Man missing, occurred on 25.03.2019 at 11:00hrs in renku Jaganadhapeta village,Polaki Mandal and reported on 03.04.2019 at 15.00hrs by the complainant Tulugu Saradha W/o Suryanarayana ,Age 30 yrs,runkujaganadhapuram village of Polaki Mandal reported that on 25-03-2019 at about 1100 hrs her father by name Yarabati Appalaramayya S/o lt Chinnavadu, Age 68 yrs, kapu by caste, Runkujaganadhapuram village left from her home for going to Narasannapeta to watch TDP MLA nomination and didn’t return back still now, Complainant, her family members and villagers causes enquiries about missing person in and around the village and surrounding villages, but could not get useful information | AA15: Total | AB15: =IF(S15="UI",DATEDIF(H15,TODAY(),"D"),"") -> 2753 | AC15: =IF(S15="UI",IF(AB15>365,"Above 1 Year",IF(AND(AB15<=365,AB15>180),"Above 6 Months",IF(AND(AB15<=180,AB15>90),"Above 3 Months",IF(AND(AB15<=90,AB15>60),"Above 60 Days",IF(AND(AB15<=60,AB15>45),"45 to 60 Days","Below 45 Days"))))),"") -> Above 1 Year | AD15: =IF(Y15<>"",DATEDIF(Y15,TODAY(),"D"),"") | AE15: =IF(AD15<>"",IF(AD15>365,"Above 1 Year",IF(AND(AD15<=365,AD15>180),"Above 6 Months",IF(AND(AD15<=180,AD15>90),"Above 3 Months",IF(AND(AD15<=90,AD15>60),"Above 60 Days",IF(AND(AD15<=60,AD15>45),"45 to 60 Days","Below 45 Days"))))),"") | AF15: D-4(Missing) | AG15: Polaki,'88/2019' | AH15: =IF(X15="SC/PRC/CC No. Awaited","",AC15) -> Above 1 Year
A16: 15 | B16: Srikakulam Sub-Division | C16: 0 | E16: Srikakulam II Town | F16: '67/2019' | G16: 420 IPC, 66-C,66-D ITA-2000-2008 | H16: 43575 | I16: Apr | J16: 2019 | K16: Cyber Crime offences | M16: Cyber Crime offences | N16: IPC | O16: Non-Grave | S16: UI | W16: For Suspect Verification | X16: Want of clues | Z16: This is a case of cheating by personation by using any communication device or computer resource that occurred Prior to 03.11.2018 at Pondara street, Kalinga hights, Balaga, Srikakulam town and reported on 20.04.2019 at 18.30 hours. where the complainant Dupam Kishor, s/o Janakeswara rao, 38 yrs, Vatarnary department, r/o Pondara street, Kalinga hights, Balaga, Srikakulam town reported that on 24.09.2018 at 09.00 hrs the accused Venkatesh informed the complainant over phone No. 8790996638 through his Nos.80175779512, 9674718043 that he has won lottery for Rs. 12,80,000 and asked to pay an amount of Rs. 12,800/- in Bank and issued an account No. 37924172660. Believing the words, he deposited the said amount. On 12.10.2018 he received phone call to Sonia Mehatha asked to pay an amount of Rs | AA16: Total | AB16: =IF(S16="UI",DATEDIF(H16,TODAY(),"D"),"") -> 2736 | AC16: =IF(S16="UI",IF(AB16>365,"Above 1 Year",IF(AND(AB16<=365,AB16>180),"Above 6 Months",IF(AND(AB16<=180,AB16>90),"Above 3 Months",IF(AND(AB16<=90,AB16>60),"Above 60 Days",IF(AND(AB16<=60,AB16>45),"45 to 60 Days","Below 45 Days"))))),"") -> Above 1 Year | AD16: =IF(Y16<>"",DATEDIF(Y16,TODAY(),"D"),"") | AE16: =IF(AD16<>"",IF(AD16>365,"Above 1 Year",IF(AND(AD16<=365,AD16>180),"Above 6 Months",IF(AND(AD16<=180,AD16>90),"Above 3 Months",IF(AND(AD16<=90,AD16>60),"Above 60 Days",IF(AND(AD16<=60,AD16>45),"45 to 60 Days","Below 45 Days"))))),"") | AF16: Cyber Cell | AG16: Srikakulam II Town,'67/2019' | AH16: =IF(X16="SC/PRC/CC No. Awaited","",AC16) -> Above 1 Year
A17: 16 | B17: Srikakulam Sub-Division | C17: 0 | E17: Srikakulam II Town | F17: '70/2019' | G17: 66-C,66-D ITA-2000-2008 | H17: 43578 | I17: Apr | J17: 2019 | K17: Cyber Crime offences | M17: Cyber Crime offences | N17: IPC | O17: Non-Grave | S17: UI | W17: For Suspect Verification | X17: Want of clues | Z17: Occurred on prior to 09.04.2019 at Gandi Nagar, Illisipuram junction, Srikakulam town and reported on 23.04.2019 at 10.30 hrs, where in the Complainant Mudu Ramji Naik S/o late Sriramulu, age 35 years, S.T. (Lambadi) by caste, Illisipuram Srikakulam reported that he is working as Asst. Professor at Ambedkar University. He has an Account in Andhra Bank with No.01810100003013 and its credit Card No.4373782067435002. On 04-04-2019 at 05.15 PM, he received a phone call from an unknown person with SIM No.9169764561 and collected his credit card number by deceiving that he would provide SBI Credit card in addition to the Andhra Bank Credit Card. After some time, he asked OTP numbers which are received to his mobile by that time by informing that the OTP numbers are required to make cross check. | AA17: Total | AB17: =IF(S17="UI",DATEDIF(H17,TODAY(),"D"),"") -> 2733 | AC17: =IF(S17="UI",IF(AB17>365,"Above 1 Year",IF(AND(AB17<=365,AB17>180),"Above 6 Months",IF(AND(AB17<=180,AB17>90),"Above 3 Months",IF(AND(AB17<=90,AB17>60),"Above 60 Days",IF(AND(AB17<=60,AB17>45),"45 to 60 Days","Below 45 Days"))))),"") -> Above 1 Year | AD17: =IF(Y17<>"",DATEDIF(Y17,TODAY(),"D"),"") | AE17: =IF(AD17<>"",IF(AD17>365,"Above 1 Year",IF(AND(AD17<=365,AD17>180),"Above 6 Months",IF(AND(AD17<=180,AD17>90),"Above 3 Months",IF(AND(AD17<=90,AD17>60),"Above 60 Days",IF(AND(AD17<=60,AD17>45),"45 to 60 Days","Below 45 Days"))))),"") | AF17: Cyber Cell | AG17: Srikakulam II Town,'70/2019' | AH17: =IF(X17="SC/PRC/CC No. Awaited","",AC17) -> Above 1 Year
A18: 17 | B18: Srikakulam Sub-Division | C18: Srikakulam Rural Circle | E18: Gara | F18: '97/2019' | G18: Woman Missing Person | H18: 43593 | I18: May | J18: 2019 | K18: Missing Cases | L18: Women Missing | M18: Missing Cases | N18: Missing | O18: Non-Grave | S18: UI | W18: Want of clues | X18: Want of clues | Z18: This is a case of woman missing occurred on 24.04.2018 at 13.00 hrs at Vadapalem village, Gara mandal and reported on 08.05.2019 at 10.00 hrs, in which the complainant Surada Rajesh s/o lt Rama Rao, 24 yrs, Vadapalem village, Gara Manual working as fisher man at Veeravali town, Gujarath and he reported that his wife Surada Varalakshmi w/o Rajesh, 22 years, vadabalija by caste, Vadapalem village, Gara Mandal, on 24.04.2018 he received information from his elder brother at about 13.00 hrs his wife left from his home for purchasing vegetables and did not returned, on that he come back to home and searched here and there and their relatives houses for his wife, but got no information, then he came to P.S. on 08.05.2019 and gave the report. | AA18: Total | AB18: =IF(S18="UI",DATEDIF(H18,TODAY(),"D"),"") -> 2718 | AC18: =IF(S18="UI",IF(AB18>365,"Above 1 Year",IF(AND(AB18<=365,AB18>180),"Above 6 Months",IF(AND(AB18<=180,AB18>90),"Above 3 Months",IF(AND(AB18<=90,AB18>60),"Above 60 Days",IF(AND(AB18<=60,AB18>45),"45 to 60 Days","Below 45 Days"))))),"") -> Above 1 Year | AD18: =IF(Y18<>"",DATEDIF(Y18,TODAY(),"D"),"") | AE18: =IF(AD18<>"",IF(AD18>365,"Above 1 Year",IF(AND(AD18<=365,AD18>180),"Above 6 Months",IF(AND(AD18<=180,AD18>90),"Above 3 Months",IF(AND(AD18<=90,AD18>60),"Above 60 Days",IF(AND(AD18<=60,AD18>45),"45 to 60 Days","Below 45 Days"))))),"") | AF18: D-4(Missing) | AG18: Gara,'97/2019' | AH18: =IF(X18="SC/PRC/CC No. Awaited","",AC18) -> Above 1 Year
A19: 18 | B19: Kasibugga Sub-Division | C19: Kasibugga Rural Circle | E19: Vajrapukothuru | F19: '81/2019' | G19: Woman,Girl,Boy Missing Person | H19: 43596 | I19: May | J19: 2019 | K19: Missing Cases | L19: Women Missing | M19: Missing Cases | N19: Missing | O19: Non-Grave | S19: UI | W19: Want of clues | X19: Want of clues | Z19: Occurred on 02.02.2019 at the house of the complainant Garudabhadra village, Vajrapukotturu PS and reported on 11.05.2019 at 19.00 hrs in which the complainant Arli Kalyan, s/o Danesh, 38 yrs, Jalari by caste, Garudabhadra village, Vajrapukotturu Mandal reported that his wife Sirisha, aged about 32 yrs left the house with their two children i.e. Son Arli Akhil aged about 5 yrs and Daughter Jahnavi aged about 8 yrs left the house telling him that she was going to her parents house at Visakhapatnam but did not return back home. Late he came to know that she had gone with his villager Burjupeta Venkatesh, s/o Krishna Rao, 25 yrs, Rajaka by caste. | AA19: Total | AB19: =IF(S19="UI",DATEDIF(H19,TODAY(),"D"),"") -> 2715 | AC19: =IF(S19="UI",IF(AB19>365,"Above 1 Year",IF(AND(AB19<=365,AB19>180),"Above 6 Months",IF(AND(AB19<=180,AB19>90),"Above 3 Months",IF(AND(AB19<=90,AB19>60),"Above 60 Days",IF(AND(AB19<=60,AB19>45),"45 to 60 Days","Below 45 Days"))))),"") -> Above 1 Year | AD19: =IF(Y19<>"",DATEDIF(Y19,TODAY(),"D"),"") | AE19: =IF(AD19<>"",IF(AD19>365,"Above 1 Year",IF(AND(AD19<=365,AD19>180),"Above 6 Months",IF(AND(AD19<=180,AD19>90),"Above 3 Months",IF(AND(AD19<=90,AD19>60),"Above 60 Days",IF(AND(AD19<=60,AD19>45),"45 to 60 Days","Below 45 Days"))))),"") | AF19: D-4(Missing) | AG19: Vajrapukothuru,'81/2019' | AH19: =IF(X19="SC/PRC/CC No. Awaited","",AC19) -> Above 1 Year
A20: 19 | B20: Tekkali Sub-Division | C20: Narasannapeta Circle | E20: Polaki | F20: '123/2019' | G20: Man Missing Person | H20: 43603 | I20: May | J20: 2019 | K20: Missing Cases | L20: Man Missing | M20: Missing Cases | N20: Missing | O20: Non-Grave | S20: UI | W20: Want of clues | X20: Want of clues | Z20: This is a case of Man missing, occurred on 12.05.2019 at 11:00hrs in Apparaopeta Colony,Polaki Mandal and reported on 18.05.2019 at 18.00Hrs by the complainant Linguberi Appa rao s/o Jogulu, age-45Years, caste by Srisaina, apparaopeta Colony, Polaki mandal reported that on 12.05.2019 at about 1100 hrs her father by name linguberi Jogulu S/o late Yerrayya,age- 82years, caste by srisaina, apparaopeta Colony, Polaki mandal. the missing person was mental disordered . On left from her home and didn’t return back still now, Complainant, her family members and villagers causes enquiries about missing person in and around the village and surrounding villages, but could not get useful information. | AA20: Total | AB20: =IF(S20="UI",DATEDIF(H20,TODAY(),"D"),"") -> 2708 | AC20: =IF(S20="UI",IF(AB20>365,"Above 1 Year",IF(AND(AB20<=365,AB20>180),"Above 6 Months",IF(AND(AB20<=180,AB20>90),"Above 3 Months",IF(AND(AB20<=90,AB20>60),"Above 60 Days",IF(AND(AB20<=60,AB20>45),"45 to 60 Days","Below 45 Days"))))),"") -> Above 1 Year | AD20: =IF(Y20<>"",DATEDIF(Y20,TODAY(),"D"),"") | AE20: =IF(AD20<>"",IF(AD20>365,"Above 1 Year",IF(AND(AD20<=365,AD20>180),"Above 6 Months",IF(AND(AD20<=180,AD20>90),"Above 3 Months",IF(AND(AD20<=90,AD20>60),"Above 60 Days",IF(AND(AD20<=60,AD20>45),"45 to 60 Days","Below 45 Days"))))),"") | AF20: D-4(Missing) | AG20: Polaki,'123/2019' | AH20: =IF(X20="SC/PRC/CC No. Awaited","",AC20) -> Above 1 Year
A21: 20 | B21: Tekkali Sub-Division | C21: Kothuru Circle | E21: Kothuru | F21: '125/2019' | G21: Man Missing Person | H21: 43612 | I21: May | J21: 2019 | K21: Missing Cases | L21: Man Missing | M21: Missing Cases | N21: Missing | O21: Non-Grave | S21: UI | W21: Want of clues | X21: Want of clues | Z21: Occurred on 19.05.2019 at about 10.30 hrs at Nivagam bus station and reported on 27.05.2019 at about 12.00 hrs which the complainant Kolleti Raju s/o Suryanarayana, age 45 yrs, Rajaka, Sigipuram village, Pathapatnam Mandal reported that his father Kolleti Suryanarayana s/o late busayya, 70 yrs went marriage at Sirusuvada village and returned from there and waiting for a bus at Nivagam village in order to come their village and missed from there | AA21: Total | AB21: =IF(S21="UI",DATEDIF(H21,TODAY(),"D"),"") -> 2699 | AC21: =IF(S21="UI",IF(AB21>365,"Above 1 Year",IF(AND(AB21<=365,AB21>180),"Above 6 Months",IF(AND(AB21<=180,AB21>90),"Above 3 Months",IF(AND(AB21<=90,AB21>60),"Above 60 Days",IF(AND(AB21<=60,AB21>45),"45 to 60 Days","Below 45 Days"))))),"") -> Above 1 Year | AD21: =IF(Y21<>"",DATEDIF(Y21,TODAY(),"D"),"") | AE21: =IF(AD21<>"",IF(AD21>365,"Above 1 Year",IF(AND(AD21<=365,AD21>180),"Above 6 Months",IF(AND(AD21<=180,AD21>90),"Above 3 Months",IF(AND(AD21<=90,AD21>60),"Above 60 Days",IF(AND(AD21<=60,AD21>45),"45 to 60 Days","Below 45 Days"))))),"") | AF21: D-4(Missing) | AG21: Kothuru,'125/2019' | AH21: =IF(X21="SC/PRC/CC No. Awaited","",AC21) -> Above 1 Year
A22: 21 | B22: Kasibugga Sub-Division | C22: Sompeta Circle | E22: Baruva | F22: '57/2019' | G22: Man Missing Person | H22: 43614 | I22: May | J22: 2019 | K22: Missing Cases | L22: Man Missing | M22: Missing Cases | N22: Missing | O22: Non-Grave | S22: UI | W22: Want of clues | X22: Want of clues | Z22: This is a case of man Missing, which occurred on 16-05-2019 at about 17.15 hrs from baruvakotturu, baruva village of Sompeta Mandal and reported on 29-05-2019 at 12.30 hrs, wherein the complainant Ambati Dandasi, S/o Late Jagannaikulu, 52 yrs., tylor,Baruva kotturu village, Sompeta mandal stated that on 16.05.2019 at 17.15 hrs., his Son came to Grand mother House in summer holidays at Nadumuru village , sompeta mandal. That day his son missing did not returned in the evening and there from he found missing. | AA22: Total | AB22: =IF(S22="UI",DATEDIF(H22,TODAY(),"D"),"") -> 2697 | AC22: =IF(S22="UI",IF(AB22>365,"Above 1 Year",IF(AND(AB22<=365,AB22>180),"Above 6 Months",IF(AND(AB22<=180,AB22>90),"Above 3 Months",IF(AND(AB22<=90,AB22>60),"Above 60 Days",IF(AND(AB22<=60,AB22>45),"45 to 60 Days","Below 45 Days"))))),"") -> Above 1 Year | AD22: =IF(Y22<>"",DATEDIF(Y22,TODAY(),"D"),"") | AE22: =IF(AD22<>"",IF(AD22>365,"Above 1 Year",IF(AND(AD22<=365,AD22>180),"Above 6 Months",IF(AND(AD22<=180,AD22>90),"Above 3 Months",IF(AND(AD22<=90,AD22>60),"Above 60 Days",IF(AND(AD22<=60,AD22>45),"45 to 60 Days","Below 45 Days"))))),"") | AF22: D-4(Missing) | AG22: Baruva,'57/2019' | AH22: =IF(X22="SC/PRC/CC No. Awaited","",AC22) -> Above 1 Year
A23: 22 | B23: Srikakulam Sub-Division | C23: 0 | E23: Srikakulam II Town | F23: '94/2019' | G23: 420 IPC, 66-C,66-D ITA-2000-2008 | H23: 43622 | I23: Jun | J23: 2019 | K23: Cyber Crime offences | M23: Cyber Crime offences | N23: IPC | O23: Non-Grave | S23: UI | W23: For Suspect Verification | X23: Want of clues | Z23: The Complainant Dadirao Venkata Kanaka Mahalaxmi Aswini Kumari W/o Vandranki Srinivasa Rao, age 43 years, Patnaik by caste, Kattera Veedhi, Srikakulam town reported that she has a bank account with Debit Card in State Bank of India with A/C No.11152457031. On 06-06-2019 at 02.46PM, one unknown person called with his mobile No.9407300859 to her mobile No.9441123083, by introducing himself that he is calling from S.B.I. Bank, he collected ATM Card Number and CVV number. By believing him, she informed all details including OTP numbers which were received three times to her mobile numbers. Later an amount of Rs.10,999/-, 31,499/- and 7,297 total Rs.49,795/- was transferred from her bank account. | AA23: Total | AB23: =IF(S23="UI",DATEDIF(H23,TODAY(),"D"),"") -> 2689 | AC23: =IF(S23="UI",IF(AB23>365,"Above 1 Year",IF(AND(AB23<=365,AB23>180),"Above 6 Months",IF(AND(AB23<=180,AB23>90),"Above 3 Months",IF(AND(AB23<=90,AB23>60),"Above 60 Days",IF(AND(AB23<=60,AB23>45),"45 to 60 Days","Below 45 Days"))))),"") -> Above 1 Year | AD23: =IF(Y23<>"",DATEDIF(Y23,TODAY(),"D"),"") | AE23: =IF(AD23<>"",IF(AD23>365,"Above 1 Year",IF(AND(AD23<=365,AD23>180),"Above 6 Months",IF(AND(AD23<=180,AD23>90),"Above 3 Months",IF(AND(AD23<=90,AD23>60),"Above 60 Days",IF(AND(AD23<=60,AD23>45),"45 to 60 Days","Below 45 Days"))))),"") | AF23: Cyber Cell | AG23: Srikakulam II Town,'94/2019' | AH23: =IF(X23="SC/PRC/CC No. Awaited","",AC23) -> Above 1 Year
A24: 23 | B24: Tekkali Sub-Division | C24: Tekkali Rural Circle | E24: Nandigam | F24: '103/2019' | G24: Man Missing Person | H24: 43625 | I24: Jun | J24: 2019 | K24: Missing Cases | L24: Man Missing | M24: Missing Cases | N24: Missing | O24: Non-Grave | S24: Police Disposal | W24: Want of clues | X24: Finalized | Z24: Occurred on 14.05.2019 at Deenabandupuram village, Nandigam Mandal and reported on 09.06.2019 at 17.30 hrs in which the complainant Sonapuram Laxmi, w/o Lavanna @ Kalavayya, 28 yrs, Deenabandupuram village, Nandigam Mandal reported that her husband Sonapuram Lavanna, s/o Ramulu, 34 yrs was eking livelihood at Guntur came to the village on 13.05.2019 to attend a function. On 14.05.2019 he attended the function and after that he made a call to her and stated that he was going to Guntur. From then he did not come to her or called her and his phone was switched off. | AA24: Total | AB24: =IF(S24="UI",DATEDIF(H24,TODAY(),"D"),"") | AC24: =IF(S24="UI",IF(AB24>365,"Above 1 Year",IF(AND(AB24<=365,AB24>180),"Above 6 Months",IF(AND(AB24<=180,AB24>90),"Above 3 Months",IF(AND(AB24<=90,AB24>60),"Above 60 Days",IF(AND(AB24<=60,AB24>45),"45 to 60 Days","Below 45 Days"))))),"") | AD24: =IF(Y24<>"",DATEDIF(Y24,TODAY(),"D"),"") | AE24: =IF(AD24<>"",IF(AD24>365,"Above 1 Year",IF(AND(AD24<=365,AD24>180),"Above 6 Months",IF(AND(AD24<=180,AD24>90),"Above 3 Months",IF(AND(AD24<=90,AD24>60),"Above 60 Days",IF(AND(AD24<=60,AD24>45),"45 to 60 Days","Below 45 Days"))))),"") | AF24: D-4(Missing) | AG24: Nandigam,'103/2019' | AH24: =IF(X24="SC/PRC/CC No. Awaited","",AC24)
A25: 24 | B25: Tekkali Sub-Division | C25: Narasannapeta Circle | E25: Polaki | F25: '148/2019' | G25: 324,307,326,323 r/w 34 IPC | H25: 43639 | I25: Jun | J25: 2019 | K25: Attempt To Murder | M25: Bodily Offiences | N25: IPC | O25: Non-Grave | P25: 44188 | Q25: Yes | S25: UI | W25: Charge Sheet returned form court | X25: Charge Sheet returned form court | Y25: 44188 | Z25: This is a case of attempt to murder that occurred on 27.03.2018 at 07.00 hrs at Dubbakavanipeta village (v) Polaki (M) and reported on the same day at 13.30 hrs by the complainant Duppattla Rambabu s/o Sriramulu, age- 42years, caste kalinga, Dubbakavanipeta village, Polaki mandal , wherein the accused Dubbaka Ravi Babu and 10 others attacked the complainant and father , mother and Complainant father in law bet him Iron road and kattahuva, stick and hand , legs and stone caused bleeding injuries. due to a dispute that the complainant placed her damage the wall place by the family members of the accused | AA25: Total | AB25: =IF(S25="UI",DATEDIF(H25,TODAY(),"D"),"") -> 2672 | AC25: =IF(S25="UI",IF(AB25>365,"Above 1 Year",IF(AND(AB25<=365,AB25>180),"Above 6 Months",IF(AND(AB25<=180,AB25>90),"Above 3 Months",IF(AND(AB25<=90,AB25>60),"Above 60 Days",IF(AND(AB25<=60,AB25>45),"45 to 60 Days","Below 45 Days"))))),"") -> Above 1 Year | AD25: =IF(Y25<>"",DATEDIF(Y25,TODAY(),"D"),"") -> 2123 | AE25: =IF(AD25<>"",IF(AD25>365,"Above 1 Year",IF(AND(AD25<=365,AD25>180),"Above 6 Months",IF(AND(AD25<=180,AD25>90),"Above 3 Months",IF(AND(AD25<=90,AD25>60),"Above 60 Days",IF(AND(AD25<=60,AD25>45),"45 to 60 Days","Below 45 Days"))))),"") -> Above 1 Year | AF25: D-6(Bodily) | AG25: Polaki,'148/2019' | AH25: =IF(X25="SC/PRC/CC No. Awaited","",AC25) -> Above 1 Year
A26: 25 | B26: Srikakulam Sub-Division | C26: Srikakulam Rural Circle | E26: Srikakulam Rural | F26: '216/2019' | G26: Woman Missing Person | H26: 43669 | I26: Jul | J26: 2019 | K26: Missing Cases | L26: Women Missing | M26: Missing Cases | N26: Missing | O26: Non-Grave | S26: UI | W26: Want of clues | X26: Want of clues | Z26: Occurred on 17.07.2019 at 11.00 hrs at Reddikillipalem village, Srikakulam mandal and reported on 23.07.2019 at 18.30 hrs, where in the complainant Pandhiri Thrinadharao S/o Adhinarayana age 32 years, caste by Padhma saali, Reddikillipalem village, Srikakulam mandal reported that his mother Pandhiri Rathnalu w/o Adhinarayana age 53 years, she left home on 17.07.2019 at 11.00 hrs for go to her sister village Silagam singuvalasa villge Srikakjulam rural mandal, she didn’t go there and didn’t return back. complainant made search her friends and relations houses, didn’t found missing women. | AA26: Total | AB26: =IF(S26="UI",DATEDIF(H26,TODAY(),"D"),"") -> 2642 | AC26: =IF(S26="UI",IF(AB26>365,"Above 1 Year",IF(AND(AB26<=365,AB26>180),"Above 6 Months",IF(AND(AB26<=180,AB26>90),"Above 3 Months",IF(AND(AB26<=90,AB26>60),"Above 60 Days",IF(AND(AB26<=60,AB26>45),"45 to 60 Days","Below 45 Days"))))),"") -> Above 1 Year | AD26: =IF(Y26<>"",DATEDIF(Y26,TODAY(),"D"),"") | AE26: =IF(AD26<>"",IF(AD26>365,"Above 1 Year",IF(AND(AD26<=365,AD26>180),"Above 6 Months",IF(AND(AD26<=180,AD26>90),"Above 3 Months",IF(AND(AD26<=90,AD26>60),"Above 60 Days",IF(AND(AD26<=60,AD26>45),"45 to 60 Days","Below 45 Days"))))),"") | AF26: D-4(Missing) | AG26: Srikakulam Rural,'216/2019' | AH26: =IF(X26="SC/PRC/CC No. Awaited","",AC26) -> Above 1 Year
A27: 26 | B27: Srikakulam Sub-Division | C27: Srikakulam Rural Circle | E27: Srikakulam Rural | F27: '231/2019' | G27: 420 IPC, 66-C ITA-2000-2008 | H27: 43679 | I27: Aug | J27: 2019 | K27: Cyber Crime offences | M27: Cyber Crime offences | N27: IPC | O27: Non-Grave | S27: UI | W27: For Suspect Verification | X27: For Suspect Verification | Z27: Occurred on 11.06.2019 at 18.00 hours, reported on 02.08.2019 at 20.00 hours, where in the complainant by name Bathula Venkatamohan sathyarao S/o Late Gangayya,age 56 years, Thelaga by cste, Thilak nagar, Srikakulam rural mandal, reported that, one un known person call to him from phone no 01246771300, your not generate your credit card pin no Since 6 months and I am generate your pin number, tell me your credit card last four numbers and OTP number, complainant also gave his credit card last four numbers and OTP number, after 5 minits complainant received one SMS, that is you are purchased one mobi cwick system and debited your credit card account Rs. 38,500/-, complainant gave report to Superintendent of Police Srikakulam on spandahana on 29.07.2019. | AA27: Total | AB27: =IF(S27="UI",DATEDIF(H27,TODAY(),"D"),"") -> 2632 | AC27: =IF(S27="UI",IF(AB27>365,"Above 1 Year",IF(AND(AB27<=365,AB27>180),"Above 6 Months",IF(AND(AB27<=180,AB27>90),"Above 3 Months",IF(AND(AB27<=90,AB27>60),"Above 60 Days",IF(AND(AB27<=60,AB27>45),"45 to 60 Days","Below 45 Days"))))),"") -> Above 1 Year | AD27: =IF(Y27<>"",DATEDIF(Y27,TODAY(),"D"),"") | AE27: =IF(AD27<>"",IF(AD27>365,"Above 1 Year",IF(AND(AD27<=365,AD27>180),"Above 6 Months",IF(AND(AD27<=180,AD27>90),"Above 3 Months",IF(AND(AD27<=90,AD27>60),"Above 60 Days",IF(AND(AD27<=60,AD27>45),"45 to 60 Days","Below 45 Days"))))),"") | AF27: Cyber Cell | AG27: Srikakulam Rural,'231/2019' | AH27: =IF(X27="SC/PRC/CC No. Awaited","",AC27) -> Above 1 Year
A28: 27 | B28: Srikakulam Sub-Division | C28: J.R.Puram Circle | E28: Etcherla | F28: '196/2019' | G28: Woman Missing Person | H28: 43686 | I28: Aug | J28: 2019 | K28: Missing Cases | L28: Women Missing | M28: Missing Cases | N28: Missing | O28: Non-Grave | S28: UI | W28: Want of clues | X28: Want of clues | Z28: Occurred 07.08.2019 at 1000 hours at Ibrahimbad village and reported on 09.08..2019 at 18.00 hours by the complainant Killi Udaya Bhaskara Rao, S/o Venkata Ramana , age -23 yrs, Kalinga by caste, Ibrahimbad village, Etcherla Mandal. In which, one Seepana Santhosamma, age-53 Grandmother of the complainant left the house in the temporary absence of inmates and found missing. Despite sincere enquiries at all likely places, no clue could be elicited to locate the missing women. | AA28: Total | AB28: =IF(S28="UI",DATEDIF(H28,TODAY(),"D"),"") -> 2625 | AC28: =IF(S28="UI",IF(AB28>365,"Above 1 Year",IF(AND(AB28<=365,AB28>180),"Above 6 Months",IF(AND(AB28<=180,AB28>90),"Above 3 Months",IF(AND(AB28<=90,AB28>60),"Above 60 Days",IF(AND(AB28<=60,AB28>45),"45 to 60 Days","Below 45 Days"))))),"") -> Above 1 Year | AD28: =IF(Y28<>"",DATEDIF(Y28,TODAY(),"D"),"") | AE28: =IF(AD28<>"",IF(AD28>365,"Above 1 Year",IF(AND(AD28<=365,AD28>180),"Above 6 Months",IF(AND(AD28<=180,AD28>90),"Above 3 Months",IF(AND(AD28<=90,AD28>60),"Above 60 Days",IF(AND(AD28<=60,AD28>45),"45 to 60 Days","Below 45 Days"))))),"") | AF28: D-4(Missing) | AG28: Etcherla,'196/2019' | AH28: =IF(X28="SC/PRC/CC No. Awaited","",AC28) -> Above 1 Year
A29: 28 | B29: Srikakulam Sub-Division | C29: J.R.Puram Circle | E29: Etcherla | F29: '206/2019' | G29: Man Missing Person | H29: 43701 | I29: Aug | J29: 2019 | K29: Missing Cases | L29: Man Missing | M29: Missing Cases | N29: Missing | O29: Non-Grave | S29: UI | W29: Want of clues | X29: Want of clues | Z29: This is a case of man missing occurred prior to 24.08.2019 at Peyyalavanipeta village, Etcherla Mandal and reported on 24.08.2019 at 19.00 hrs by the complainant Tammineni Madhsudhanarao s/o Chinnarao, 39 yrs, kalinga by caste, peyyalavanipeta village, Etcherla mandal in which one Tammineni Chinnarao s/o late Rajarao, 71 yrs, kalinga by caste, peyyalavanipeta village, Etcherla mandal father of the complainant left the house in the temporary absence of inmates and found missing. Despite sincere enquiries at all likely places, no clue could be elicited to locate the missing man. | AA29: Total | AB29: =IF(S29="UI",DATEDIF(H29,TODAY(),"D"),"") -> 2610 | AC29: =IF(S29="UI",IF(AB29>365,"Above 1 Year",IF(AND(AB29<=365,AB29>180),"Above 6 Months",IF(AND(AB29<=180,AB29>90),"Above 3 Months",IF(AND(AB29<=90,AB29>60),"Above 60 Days",IF(AND(AB29<=60,AB29>45),"45 to 60 Days","Below 45 Days"))))),"") -> Above 1 Year | AD29: =IF(Y29<>"",DATEDIF(Y29,TODAY(),"D"),"") | AE29: =IF(AD29<>"",IF(AD29>365,"Above 1 Year",IF(AND(AD29<=365,AD29>180),"Above 6 Months",IF(AND(AD29<=180,AD29>90),"Above 3 Months",IF(AND(AD29<=90,AD29>60),"Above 60 Days",IF(AND(AD29<=60,AD29>45),"45 to 60 Days","Below 45 Days"))))),"") | AF29: D-4(Missing) | AG29: Etcherla,'206/2019' | AH29: =IF(X29="SC/PRC/CC No. Awaited","",AC29) -> Above 1 Year
A30: 29 | B30: Tekkali Sub-Division | C30: Narasannapeta Circle | E30: Narasannapeta | F30: '264/2019' | G30: 420 IPC, 76(1) CFA | H30: 43702 | I30: Aug | J30: 2019 | K30: Cheating | M30: White Collar Offences | N30: IPC | O30: Non-Grave | P30: 44341 | S30: UI | W30: SC/PRC/CC No. Awaited | X30: SC/PRC/CC No. Awaited | Y30: 44341 | Z30: This is a case of cheating that occurred prior to 25.08.2019 and reported on 25.08.2019 at 20.00 hrs, in which the complainant Korukonda Simhachalam S/o late Surayya, 40 yrs, Kapu by caste, Kotarupalli village, Narasannapeta Mandal reported that the accused Polaki Ramana S/o Suryanarayana and 3 others of Kotarupalli village believe deceitful words with him and collecting money Rs. 90,000/- by chit fund and did not returned to him thereby cheated him. | AA30: Total | AB30: =IF(S30="UI",DATEDIF(H30,TODAY(),"D"),"") -> 2609 | AC30: =IF(S30="UI",IF(AB30>365,"Above 1 Year",IF(AND(AB30<=365,AB30>180),"Above 6 Months",IF(AND(AB30<=180,AB30>90),"Above 3 Months",IF(AND(AB30<=90,AB30>60),"Above 60 Days",IF(AND(AB30<=60,AB30>45),"45 to 60 Days","Below 45 Days"))))),"") -> Above 1 Year | AD30: =IF(Y30<>"",DATEDIF(Y30,TODAY(),"D"),"") -> 1970 | AE30: =IF(AD30<>"",IF(AD30>365,"Above 1 Year",IF(AND(AD30<=365,AD30>180),"Above 6 Months",IF(AND(AD30<=180,AD30>90),"Above 3 Months",IF(AND(AD30<=90,AD30>60),"Above 60 Days",IF(AND(AD30<=60,AD30>45),"45 to 60 Days","Below 45 Days"))))),"") -> Above 1 Year | AF30: D-6(White collar) | AG30: Narasannapeta,'264/2019' | AH30: =IF(X30="SC/PRC/CC No. Awaited","",AC30)
A31: 30 | B31: Srikakulam Sub-Division | C31: J.R.Puram Circle | E31: Etcherla | F31: '216/2019' | G31: Man Missing Person | H31: 43714 | I31: Sep | J31: 2019 | K31: Missing Cases | L31: Man Missing | M31: Missing Cases | N31: Missing | O31: Non-Grave | S31: UI | W31: Want of clues | X31: Want of clues | Z31: This is a case of Missing of mans, that occurred on 06..09..2019 13.00 hours at kuppili gedda, kuppili village, Etcherla and reported on 06..09..2019 at 20.00 hours by the complainant Balivada Dhananjayarao s/o Ramarao, Age 48 years, karnam by caste, VRO, Kuppili village, Srikakulam Mandal. In which, 4 person go to beach for photos, one person Bora Ramana reddy, s/o Appanna, 22 yrs was get into the river and at the time big waves from bay of Bengal and he was danger in the river., Nimma santhosh s/o dalappadu, 21 yrs, both are reddika by caste, kuppili village was try to save him, but they both are missing that place. till in the late evening and thereby found missing. On enquiries in and around the sea area, whereabouts of the missing 2 persons could not be traced out. | AA31: Total | AB31: =IF(S31="UI",DATEDIF(H31,TODAY(),"D"),"") -> 2597 | AC31: =IF(S31="UI",IF(AB31>365,"Above 1 Year",IF(AND(AB31<=365,AB31>180),"Above 6 Months",IF(AND(AB31<=180,AB31>90),"Above 3 Months",IF(AND(AB31<=90,AB31>60),"Above 60 Days",IF(AND(AB31<=60,AB31>45),"45 to 60 Days","Below 45 Days"))))),"") -> Above 1 Year | AD31: =IF(Y31<>"",DATEDIF(Y31,TODAY(),"D"),"") | AE31: =IF(AD31<>"",IF(AD31>365,"Above 1 Year",IF(AND(AD31<=365,AD31>180),"Above 6 Months",IF(AND(AD31<=180,AD31>90),"Above 3 Months",IF(AND(AD31<=90,AD31>60),"Above 60 Days",IF(AND(AD31<=60,AD31>45),"45 to 60 Days","Below 45 Days"))))),"") | AF31: D-4(Missing) | AG31: Etcherla,'216/2019' | AH31: =IF(X31="SC/PRC/CC No. Awaited","",AC31) -> Above 1 Year
A32: 31 | B32: Srikakulam Sub-Division | C32: 0 | E32: Srikakulam II Town | F32: '192/2019' | G32: 66-C ITA-2000-2008 | H32: 43721 | I32: Sep | J32: 2019 | K32: Cyber Crime offences | M32: Cyber Crime offences | N32: IPC | O32: Non-Grave | S32: UI | W32: For Suspect Verification | X32: Want of clues | Z32: Occurred prior to 13.09.2019 at APGVP bank, beside saraswati mahal and reported on 13.09.2019 at 19.30 hrs wherein the complainant Cheekati krishnaveni W/o chanti, age 27 yrs, Velama caste, DCCB colony, srikakulam reported that she is having bank account No: 73050902382 at APGVP Bank, beside Saraswati theatre, her account having Rs 40,000/- in the name o RD amount. on 10.09.2019 she came to know that there is no balance in her account then she went to the bank and enquired about it, then she came know that total Rs 27,500/- was withdrawn from her account on dates 20.08.2019, 28.08.2019, 30.08.2019 without her notice. Then she came to police station and gave the report | AA32: Total | AB32: =IF(S32="UI",DATEDIF(H32,TODAY(),"D"),"") -> 2590 | AC32: =IF(S32="UI",IF(AB32>365,"Above 1 Year",IF(AND(AB32<=365,AB32>180),"Above 6 Months",IF(AND(AB32<=180,AB32>90),"Above 3 Months",IF(AND(AB32<=90,AB32>60),"Above 60 Days",IF(AND(AB32<=60,AB32>45),"45 to 60 Days","Below 45 Days"))))),"") -> Above 1 Year | AD32: =IF(Y32<>"",DATEDIF(Y32,TODAY(),"D"),"") | AE32: =IF(AD32<>"",IF(AD32>365,"Above 1 Year",IF(AND(AD32<=365,AD32>180),"Above 6 Months",IF(AND(AD32<=180,AD32>90),"Above 3 Months",IF(AND(AD32<=90,AD32>60),"Above 60 Days",IF(AND(AD32<=60,AD32>45),"45 to 60 Days","Below 45 Days"))))),"") | AF32: Cyber Cell | AG32: Srikakulam II Town,'192/2019' | AH32: =IF(X32="SC/PRC/CC No. Awaited","",AC32) -> Above 1 Year
A33: 32 | B33: Srikakulam Sub-Division | C33: Srikakulam Rural Circle | E33: Srikakulam Rural | F33: '267/2019' | G33: 420 IPC, 66-D ITA-2000-2008 | H33: 43721 | I33: Sep | J33: 2019 | K33: Cyber Crime offences | M33: Cyber Crime offences | N33: IPC | O33: Non-Grave | S33: UI | W33: For Suspect Verification | X33: For Suspect Verification | Z33: Occurred on prior to 12.08.2019, at Gedhelavanipeta village Srikakulam rural mandal, reported on 13.09.2019 at 09.00 hours, where in the complainant Sadhu VenkataramaRAO S/o Apparao age 38 years, caste by Velama, Gedhelavanipeta village, Srikakulam rural mandal, reported that accused Miss Meria Alena send one mail to complainant, that is she is cancer patient, she died in few days, she contained 2.5 billions dollars, you build an orphanage and provide an ATM card to complainant withdrawal Rs. 10,000/- in his possession has made fraudulent remarks and 17 lakes in the account of defamation by her agent by name Mr. Adems Jones in various accounts. | AA33: Total | AB33: =IF(S33="UI",DATEDIF(H33,TODAY(),"D"),"") -> 2590 | AC33: =IF(S33="UI",IF(AB33>365,"Above 1 Year",IF(AND(AB33<=365,AB33>180),"Above 6 Months",IF(AND(AB33<=180,AB33>90),"Above 3 Months",IF(AND(AB33<=90,AB33>60),"Above 60 Days",IF(AND(AB33<=60,AB33>45),"45 to 60 Days","Below 45 Days"))))),"") -> Above 1 Year | AD33: =IF(Y33<>"",DATEDIF(Y33,TODAY(),"D"),"") | AE33: =IF(AD33<>"",IF(AD33>365,"Above 1 Year",IF(AND(AD33<=365,AD33>180),"Above 6 Months",IF(AND(AD33<=180,AD33>90),"Above 3 Months",IF(AND(AD33<=90,AD33>60),"Above 60 Days",IF(AND(AD33<=60,AD33>45),"45 to 60 Days","Below 45 Days"))))),"") | AF33: Cyber Cell | AG33: Srikakulam Rural,'267/2019' | AH33: =IF(X33="SC/PRC/CC No. Awaited","",AC33) -> Above 1 Year
A34: 33 | B34: Srikakulam Sub-Division | C34: 0 | E34: Srikakulam II Town | F34: '194/2019' | G34: 66-D,66-C ITA-2000-2008 | H34: 43722 | I34: Sep | J34: 2019 | K34: Cyber Crime offences | M34: Cyber Crime offences | N34: IPC | O34: Non-Grave | S34: UI | W34: For Suspect Verification | X34: Want of clues | Z34: This is a case of cheating and Information Technology Act, where in the complainant Boddu Rana, S/o Rama Krishna, age about 33 years, Caste by Vadabalija, Dammala street, Golkonda revu street, Srikakulam town reported that, he is working as a Manager in Hotel Nagavali, Srikakulam town. On 14.09.2019 at 15.51 hrs he got a phone call from Pune named Mr.Rakesh Sharma to the land line number of the Hotel and he made reservation to book 3 rooms A/C DLX for 3 nights from 15.09.2019 to 18.09.2019 after that the customer asked the complainant’s A/C number to pay advance, then the complainant gave his Google Pay number to him, then the customer asked to the complainant about his Google pay pin, then the complainant told his Pin, after Rs. 30,000/- amount was withdrawn from his account. Then h | AA34: Total | AB34: =IF(S34="UI",DATEDIF(H34,TODAY(),"D"),"") -> 2589 | AC34: =IF(S34="UI",IF(AB34>365,"Above 1 Year",IF(AND(AB34<=365,AB34>180),"Above 6 Months",IF(AND(AB34<=180,AB34>90),"Above 3 Months",IF(AND(AB34<=90,AB34>60),"Above 60 Days",IF(AND(AB34<=60,AB34>45),"45 to 60 Days","Below 45 Days"))))),"") -> Above 1 Year | AD34: =IF(Y34<>"",DATEDIF(Y34,TODAY(),"D"),"") | AE34: =IF(AD34<>"",IF(AD34>365,"Above 1 Year",IF(AND(AD34<=365,AD34>180),"Above 6 Months",IF(AND(AD34<=180,AD34>90),"Above 3 Months",IF(AND(AD34<=90,AD34>60),"Above 60 Days",IF(AND(AD34<=60,AD34>45),"45 to 60 Days","Below 45 Days"))))),"") | AF34: Cyber Cell | AG34: Srikakulam II Town,'194/2019' | AH34: =IF(X34="SC/PRC/CC No. Awaited","",AC34) -> Above 1 Year
